package day12;

import java.util.Scanner;

public class Exception02 {

	public static void main(String[] args) {
		//num1, num2, 연산자 입력하여 메서드 실행 
		// 메서드 호출할때 예외처리
		// 두 수를 입력받고, 연산자를 입력받아 
		
		Scanner scan = new Scanner(System.in);
		System.out.println("숫자와 연산자를 입력");
		int num1 = scan.nextInt();
		int num2 = scan.nextInt();
		String p1 = scan.next();
	
		
		calc(num1, num2, p1);
		
	}

	//기능 :사칙연산의 결과를 리턴하는 메서드 생성
	//throw를 발생시키게 되면 예외메서드를 호출하는..? 객체에게 넘기는 현상이 발생됨
	//throw를 발생시키면 메서드 선언부 끝에 throws 발생할 수 있는 예외를 반드시 적어야함.
	//'throws RuntimeException'의 경우 생략 가능
	public static double calc(int num1, int num2, String p1) throws RuntimeException {
		double res = 0;
		
		//예외처리는 앞에서 미리 해주는게 좋음.
		if((p1=="/" || p1=="%") && num2 ==0) {
		throw new RuntimeException("num2는 0이 될 수 없습니다.");
		}
			
			switch(p1) {
			case "+":
				res = num1 + num2;
				break;
			case "-":
				res = num1 - num2;
				break;
			case "*":
				res = num1 * num2;
				break;
			case "/":
				res = (double)num1 / num2;
				break;
			default:
				throw new RuntimeException(p1+"는 산술연산자가 아닙니다.");
				
			}
			return res;
			
		
		
	}
	
	
}
